<?xml version="1.0" ?>
<!-- =================================================================================== -->
<!-- |    This document was autogenerated by xacro from nomeer1_robot.xacro            | -->
<!-- |    EDITING THIS FILE BY HAND IS NOT RECOMMENDED                                 | -->
<!-- =================================================================================== -->
<robot name="nomeer1_robot">
  <!-- Specify some standard inertial calculations https://en.wikipedia.org/wiki/List_of_moments_of_inertia -->
  <!-- These make use of xacro's mathematical functionality -->
  <material name="white">
    <color rgba="1 1 1 1"/>
  </material>
  <material name="orange">
    <color rgba="1 0.3 0.1 1"/>
  </material>
  <material name="blue">
    <color rgba="0.2 0.2 1 1"/>
  </material>
  <material name="green">
    <color rgba="0.0 1.0 0.0 1.0"/>
  </material>
  <material name="black">
    <color rgba="0 0 0 1"/>
  </material>
  <link name="base_link">
    <visual name="base_visual">
      <origin rpy="0.0 0.0 0.0" xyz="0.0 0.0 0.4"/>
      <geometry>
        <box size="2.0 1.0 0.35"/>
      </geometry>
      <material name="white"/>
    </visual>
    <collision name="base_collison">
      <origin rpy="0.0 0.0 0.0" xyz="0.0 0.0 0.4"/>
      <geometry>
        <box size="4.0 2.0 1.0"/>
      </geometry>
    </collision>
    <inertial>
      <origin rpy="0 0 0" xyz="0.0 0 0.4"/>
      <mass value="30"/>
      <inertia ixx="12.5" ixy="0.0" ixz="0.0" iyy="42.5" iyz="0.0" izz="50.0"/>
    </inertial>
  </link>
  <!-- Specify some standard inertial calculations https://en.wikipedia.org/wiki/List_of_moments_of_inertia -->
  <!-- These make use of xacro's mathematical functionality -->
  <link name="camera">
    <visual name="camera_visual">
      <origin rpy="0.0 0.0 0.0" xyz="0.0 0.0 0.4"/>
      <geometry>
        <box size="0.1 0.1 0.1"/>
      </geometry>
      <material name="green"/>
    </visual>
    <collision name="camera_collision">
      <origin rpy="0.0 0.0 0.0" xyz="0.0 0.0 0.4"/>
      <geometry>
        <box size="0.1 0.1 0.1"/>
      </geometry>
    </collision>
    <inertial>
      <origin rpy="0 0 0" xyz="0.0 0 0.4"/>
      <mass value="0.1"/>
      <inertia ixx="0.0001666666666666667" ixy="0.0" ixz="0.0" iyy="0.0001666666666666667" iyz="0.0" izz="0.0001666666666666667"/>
    </inertial>
  </link>
  <link name="lidar">
    <visual name="lidar_visual">
      <origin rpy="0.0 0.0 0.0" xyz="0.0 0.0 0.4"/>
      <geometry>
        <cylinder length="0.2" radius="0.15"/>
      </geometry>
      <material name="blue"/>
    </visual>
    <collision name="lidar_collision">
      <origin rpy="0.0 0.0 0.0" xyz="0.0 0.0 0.4"/>
      <geometry>
        <cylinder length="0.2" radius="0.15"/>
      </geometry>
    </collision>
    <inertial>
      <origin rpy="0 0 0" xyz="0.0 0.0 0.4"/>
      <mass value="0.1"/>
      <inertia ixx="0.0008958333333333333" ixy="0.0" ixz="0.0" iyy="0.0008958333333333333" iyz="0.0" izz="0.001125"/>
    </inertial>
  </link>
  <link name="wheel1">
    <visual name="wheel1_visual">
      <origin rpy="0.0 1.5707 1.5707" xyz="0.0 0.0 0.4"/>
      <geometry>
        <cylinder length="0.2" radius="0.4"/>
      </geometry>
      <material name="black"/>
    </visual>
    <collision name="wheel1_collision">
      <origin rpy="0.0 1.5707 1.5707" xyz="0.0 0.0 0.4"/>
      <geometry>
        <cylinder length="0.2" radius="0.4"/>
      </geometry>
    </collision>
    <inertial>
      <origin rpy="0.0 1.5707 1.5707" xyz="0.0 0.0 0.4"/>
      <mass value="5.0"/>
      <inertia ixx="0.2166666666666667" ixy="0.0" ixz="0.0" iyy="0.2166666666666667" iyz="0.0" izz="0.4000000000000001"/>
    </inertial>
  </link>
  <link name="wheel2">
    <visual name="wheel2_visual">
      <origin rpy="0.0 1.5707 1.5707" xyz="0.0 0.0 0.4"/>
      <geometry>
        <cylinder length="0.2" radius="0.4"/>
      </geometry>
      <material name="black"/>
    </visual>
    <collision name="wheel2_collision">
      <origin rpy="0.0 1.5707 1.5707" xyz="0.0 0.0 0.4"/>
      <geometry>
        <cylinder length="0.2" radius="0.4"/>
      </geometry>
    </collision>
    <inertial>
      <origin rpy="0.0 1.5707 1.5707" xyz="0.0 0.0 0.4"/>
      <mass value="5.0"/>
      <inertia ixx="0.2166666666666667" ixy="0.0" ixz="0.0" iyy="0.2166666666666667" iyz="0.0" izz="0.4000000000000001"/>
    </inertial>
  </link>
  <link name="wheel3">
    <visual name="wheel3_visual">
      <origin rpy="0.0 1.5707 1.5707" xyz="0.0 0.0 0.4"/>
      <geometry>
        <cylinder length="0.2" radius="0.4"/>
      </geometry>
      <material name="black"/>
    </visual>
    <collision name="wheel3_collision">
      <origin rpy="0.0 1.5707 1.5707" xyz="0.0 0.0 0.4"/>
      <geometry>
        <cylinder length="0.2" radius="0.4"/>
      </geometry>
    </collision>
    <inertial>
      <origin rpy="0.0 1.5707 1.5707" xyz="0.0 0.0 0.4"/>
      <mass value="5.0"/>
      <inertia ixx="0.2166666666666667" ixy="0.0" ixz="0.0" iyy="0.2166666666666667" iyz="0.0" izz="0.4000000000000001"/>
    </inertial>
  </link>
  <link name="wheel4">
    <visual name="wheel4_visual">
      <origin rpy="0.0 1.5707 1.5707" xyz="0.0 0.0 0.4"/>
      <geometry>
        <cylinder length="0.2" radius="0.4"/>
      </geometry>
      <material name="black"/>
    </visual>
    <collision name="wheel4_collision">
      <origin rpy="0.0 1.5707 1.5707" xyz="0.0 0.0 0.4"/>
      <geometry>
        <cylinder length="0.2" radius="0.4"/>
      </geometry>
    </collision>
    <inertial>
      <origin rpy="0.0 1.5707 1.5707" xyz="0.0 0.0 0.4"/>
      <mass value="5.0"/>
      <inertia ixx="0.2166666666666667" ixy="0.0" ixz="0.0" iyy="0.2166666666666667" iyz="0.0" izz="0.4000000000000001"/>
    </inertial>
  </link>
  <!--create joints-->
  <!--camera joint-->
  <joint name="base_camera" type="fixed">
    <parent link="base_link"/>
    <child link="camera"/>
    <origin rpy="0.0 0.0 0.0" xyz="1.0 0.0 0.0"/>
  </joint>
  <!--lidar joint-->
  <joint name="base_lidar" type="fixed">
    <parent link="base_link"/>
    <child link="lidar"/>
    <origin rpy="0.0 0.0 0.0" xyz="0.0 0.0 0.225"/>
  </joint>
  <!--wheel1 joint-->
  <joint name="base_wheel1" type="continuous">
    <parent link="base_link"/>
    <child link="wheel1"/>
    <origin rpy="0.0 0.0 0.0" xyz="0.6 0.6 0.0"/>
    <axis xyz="0.0 1.0 0.0"/>
  </joint>
  <!--wheel2 joint-->
  <joint name="base_wheel2" type="continuous">
    <parent link="base_link"/>
    <child link="wheel2"/>
    <origin rpy="0.0 0.0 0.0" xyz="-0.6 0.6 0.0"/>
    <axis xyz="0.0 1.0 0.0"/>
  </joint>
  <!--wheel3 joint-->
  <joint name="base_wheel3" type="continuous">
    <parent link="base_link"/>
    <child link="wheel3"/>
    <origin rpy="0.0 0.0 0.0" xyz="0.6 -0.6 0.0"/>
    <axis xyz="0.0 -1.0 0.0"/>
  </joint>
  <!--wheel4 joint-->
  <joint name="base_wheel4" type="continuous">
    <parent link="base_link"/>
    <child link="wheel4"/>
    <origin rpy="0.0 0.0 0.0" xyz="-0.6 -0.6 0.0"/>
    <axis xyz="0.0 -1.0 0.0"/>
  </joint>
</robot>

