<?xml version="1.0" ?>
<!-- =================================================================================== -->
<!-- |    This document was autogenerated by xacro from robot.xacro                    | -->
<!-- |    EDITING THIS FILE BY HAND IS NOT RECOMMENDED                                 | -->
<!-- =================================================================================== -->
<robot name="autonomous_robot_1">
  <!--<xacro:camera_link name="camera_link_1"/>-->
  <!-- Specify some standard inertial calculations https://en.wikipedia.org/wiki/List_of_moments_of_inertia -->
  <!-- These make use of xacro's mathematical functionality -->
  <material name="white">
    <color rgba="1 1 1 1"/>
  </material>
  <material name="orange">
    <color rgba="1 0.3 0.1 1"/>
  </material>
  <material name="blue">
    <color rgba="0.2 0.2 1 1"/>
  </material>
  <material name="green">
    <color rgba="0.0 1.0 0.0 1.0"/>
  </material>
  <material name="black">
    <color rgba="0 0 0 1"/>
  </material>
  <link name="base_link">
    <visual name="base_link_visual">
      <origin rpy="0.0 0.0 0.0" xyz="0.0 0.0 0.5"/>
      <geometry>
        <box size="2.25 2.0 0.6"/>
      </geometry>
      <material name="white"/>
    </visual>
    <collision name="base_link_collison">
      <origin rpy="0.0 0.0 0.0" xyz="0.0 0.0 0.5"/>
      <geometry>
        <box size="2.25 2.0 0.6"/>
      </geometry>
    </collision>
    <inertial>
      <origin rpy="0 0 0" xyz="0.0 0 0.4"/>
      <mass value="30"/>
      <inertia ixx="10.9" ixy="0.0" ixz="0.0" iyy="13.55625" iyz="0.0" izz="22.65625"/>
    </inertial>
  </link>
  <link name="body_link">
    <visual name="body_link_visual">
      <origin rpy="0.0 1.5708 0.0" xyz="0.95 0.0 1.6"/>
      <geometry>
        <box size="2.0 2.0 0.35"/>
      </geometry>
      <material name="white"/>
    </visual>
    <collision name="body_link_collison">
      <origin rpy="0.0 1.5708 0.0" xyz="0.95 0.0 1.6"/>
      <geometry>
        <box size="2.0 2.0 0.35"/>
      </geometry>
    </collision>
    <inertial>
      <origin rpy="0 0 0" xyz="2.0 2.0 0.35"/>
      <mass value="30"/>
      <inertia ixx="12.5" ixy="0.0" ixz="0.0" iyy="42.5" iyz="0.0" izz="50.0"/>
    </inertial>
  </link>
  <link name="wheel1_link">
    <visual name="wheel1_link_visual">
      <origin rpy="0.0 1.5707 1.5707" xyz="0.0 0.0 0.5"/>
      <geometry>
        <cylinder length="0.2" radius="0.5"/>
      </geometry>
      <material name="black"/>
    </visual>
    <collision name="wheel1_link_collision">
      <origin rpy="0.0 1.5707 1.5707" xyz="0.0 0.0 0.5"/>
      <geometry>
        <cylinder length="0.2" radius="0.5"/>
      </geometry>
    </collision>
    <inertial>
      <origin rpy="0.0 1.5707 1.5707" xyz="0.0 0.0 0.5"/>
      <mass value="5.0"/>
      <inertia ixx="0.32916666666666666" ixy="0.0" ixz="0.0" iyy="0.32916666666666666" iyz="0.0" izz="0.625"/>
    </inertial>
  </link>
  <link name="wheel2_link">
    <visual name="wheel2_link_visual">
      <origin rpy="0.0 1.5707 1.5707" xyz="0.0 0.0 0.5"/>
      <geometry>
        <cylinder length="0.2" radius="0.5"/>
      </geometry>
      <material name="black"/>
    </visual>
    <collision name="wheel2_link_collision">
      <origin rpy="0.0 1.5707 1.5707" xyz="0.0 0.0 0.5"/>
      <geometry>
        <cylinder length="0.2" radius="0.5"/>
      </geometry>
    </collision>
    <inertial>
      <origin rpy="0.0 1.5707 1.5707" xyz="0.0 0.0 0.5"/>
      <mass value="5.0"/>
      <inertia ixx="0.32916666666666666" ixy="0.0" ixz="0.0" iyy="0.32916666666666666" iyz="0.0" izz="0.625"/>
    </inertial>
  </link>
  <link name="caster_link">
    <visual name="caster_link_visual">
      <origin rpy="0.0 0.0 0.0" xyz="0.0 0.0 0.15"/>
      <geometry>
        <sphere radius="0.15"/>
      </geometry>
      <material name="orange"/>
    </visual>
    <collision name="caster_link_collision">
      <origin rpy="0.0 0.0 0.0" xyz="0.0 0.0 0.15"/>
      <geometry>
        <sphere radius="0.15"/>
      </geometry>
      <surface>
        <friction>
          <ode>
            <mu>0</mu>
            <mu2>0</mu2>
            <slip1>1.0</slip1>
            <slip2>1.0</slip2>
          </ode>
        </friction>
      </surface>
    </collision>
    <inertial>
      <origin rpy="0.0 0.0 0.0" xyz="0.0 0.0 0.15"/>
      <mass value="1.5"/>
      <inertia ixx="0.013500000000000002" ixy="0.0" ixz="0.0" iyy="0.013500000000000002" iyz="0.0" izz="0.013500000000000002"/>
    </inertial>
  </link>
  <link name="lidar_link">
    <visual name="lidar_link_visual">
      <origin rpy="0.0 0.0 0.0" xyz="0.0 0.0 0.4"/>
      <geometry>
        <cylinder length="0.2" radius="0.15"/>
      </geometry>
      <material name="blue"/>
    </visual>
    <collision name="lidar_link_collision">
      <origin rpy="0.0 0.0 0.0" xyz="0.0 0.0 0.4"/>
      <geometry>
        <cylinder length="0.2" radius="0.15"/>
      </geometry>
    </collision>
    <inertial>
      <origin rpy="0 0 0" xyz="0.0 0.0 0.4"/>
      <mass value="0.1"/>
      <inertia ixx="0.0008958333333333333" ixy="0.0" ixz="0.0" iyy="0.0008958333333333333" iyz="0.0" izz="0.001125"/>
    </inertial>
  </link>
  <link name="camera_link">
    <visual name="camera_link_visual">
      <origin rpy="0.0 0.0 0.0" xyz="0.0 0.0 0.4"/>
      <geometry>
        <box size="0.2 0.2 0.2"/>
      </geometry>
      <material name="green"/>
    </visual>
    <collision name="camera_link_collision">
      <origin rpy="0.0 0.0 0.0" xyz="0.0 0.0 0.4"/>
      <geometry>
        <box size="0.2 0.2 0.2"/>
      </geometry>
    </collision>
    <inertial>
      <origin rpy="0 0 0" xyz="0.0 0 0.4"/>
      <mass value="0.2"/>
      <inertia ixx="0.0013333333333333335" ixy="0.0" ixz="0.0" iyy="0.0013333333333333335" iyz="0.0" izz="0.0013333333333333335"/>
    </inertial>
  </link>
  <!--create joints with base-->
  <!--body base joint-->
  <joint name="joint_name" type="fixed">
    <origin rpy="0.0 0.0 0.0" xyz="0.0 0.0 0.0"/>
    <parent link="base_link"/>
    <child link="body_link"/>
  </joint>
  <!--wheel1 joint-->
  <joint name="wheel1_base_joint" type="continuous">
    <origin rpy="0.0 0.0 0.0" xyz="0.3 1.1 0.0"/>
    <parent link="base_link"/>
    <child link="wheel1_link"/>
    <axis xyz="0.0 0.0 0.0"/>
  </joint>
  <!--wheel2 joint-->
  <joint name="wheel2_base_joint" type="continuous">
    <origin rpy="0.0 0.0 0.0" xyz="0.3 -1.1 0.0"/>
    <parent link="base_link"/>
    <child link="wheel2_link"/>
    <axis xyz="0.0 0.0 0.0"/>
  </joint>
  <!--caster joint-->
  <joint name="caster_base_joint" type="fixed">
    <origin rpy="0.0 0.0 0.0" xyz="-0.8 0.0 0.0"/>
    <parent link="base_link"/>
    <child link="caster_link"/>
  </joint>
  <!--lidar joint-->
  <joint name="lidar_base_joint" type="fixed">
    <origin rpy="0.0 0.0 0.0" xyz="0.0 0.0 0.45"/>
    <parent link="base_link"/>
    <child link="lidar_link"/>
  </joint>
  <!--camera joint-->
  <joint name="camera_base_joint" type="fixed">
    <origin rpy="0.0 0.0 0.0" xyz="0.8 0.0 2.0"/>
    <parent link="base_link"/>
    <child link="camera_link"/>
  </joint>
</robot>

